# Syntax Error Fixed - DiseaseDetectionService.kt

## Problem Fixed
**Syntax error in exception handling structure** - The code had a malformed try-catch block where the second `catch (e: Exception)` block was missing, leaving orphaned code statements.

## What Was Wrong

### Before (Broken Code):
```kotlin
} catch (e: retrofit2.HttpException) {
    Log.w("DiseaseDetection", "HTTP error ${e.code()}: ${e.message()}")
    
    try {
        val errorResponse = handleHttpError(e)
        Log.d("DiseaseDetection", "Legitimate API rejection: ${errorResponse.message}")
        errorResponse
    } catch (fallbackException: Exception) {
        Log.w("DiseaseDetection", "Server error detected, falling back to offline...")
        performOfflineDetection(bitmap, startTime, "server_error_fallback")
    }
}
    // ‚ùå These lines were OUTSIDE any catch block - syntax error!
    Log.w("DiseaseDetection", "Online detection failed, falling back to offline: ${e.message}")
    performOfflineDetection(bitmap, startTime, "online_fallback")
}
```

The problem: After the `HttpException` catch block closed with `}`, there were statements that referenced `e` (the exception variable), but they weren't inside any catch block. This is invalid Kotlin syntax.

### After (Fixed Code):
```kotlin
} catch (e: retrofit2.HttpException) {
    Log.w("DiseaseDetection", "HTTP error ${e.code()}: ${e.message()}")
    
    try {
        val errorResponse = handleHttpError(e)
        Log.d("DiseaseDetection", "Legitimate API rejection: ${errorResponse.message}")
        errorResponse
    } catch (fallbackException: Exception) {
        Log.w("DiseaseDetection", "Server error detected, falling back to offline...")
        performOfflineDetection(bitmap, startTime, "server_error_fallback")
    }
} catch (e: Exception) {
    // ‚úÖ Now properly inside a catch block for general exceptions
    Log.w("DiseaseDetection", "Online detection failed, falling back to offline: ${e.message}")
    performOfflineDetection(bitmap, startTime, "online_fallback")
}
```

## Error Flow Now Works Correctly

The try-catch structure now properly handles three scenarios:

1. **Success Path**: Online detection succeeds ‚Üí Return results
2. **HTTP Error (400)**: "Not a rice leaf" ‚Üí Return error response  
3. **HTTP Error (502/503/504)**: Server error ‚Üí Throw exception ‚Üí Fall back to offline
4. **Other Exceptions**: Network/timeout issues ‚Üí Fall back to offline

## Testing

The app should now:
- ‚úÖ Compile without errors
- ‚úÖ Handle 502 errors by falling back to offline detection
- ‚úÖ Show "Server temporarily unavailable. Using offline analysis."
- ‚úÖ Display offline detection results instead of "not a rice leaf"

## Next Steps

1. **Clean and rebuild the project**
2. **Test with a rice leaf image** when your server returns 502 error
3. **Check LogCat** for these messages:
   ```
   W/DiseaseDetection: HTTP error 502: API returned HTML instead of JSON
   W/DiseaseDetection: Server error detected, falling back to offline
   D/DiseaseDetection: Using offline ML model
   ```

The fix is complete and ready to test! üéâ

